## 异常处理机制

`try-catch-finally` 是异常处理机制中常用的结构，它允许程序在运行时捕获和处理可能出现的异常，从而避免程序因未处理的错误而终止。以下是其基本用法和详细说明：

---

### 基本结构
```python
try:
    # 尝试运行的代码块
    # 可能会引发异常的代码
except ExceptionType as e:
    # 捕获特定异常，并处理异常
    # ExceptionType 是要捕获的异常类型
finally:
    # 无论是否发生异常都会执行的代码块
```

### 关键部分说明
1. **`try` 块**：
   - 包含可能引发异常的代码。
   - 如果代码执行过程中没有异常，`except` 和 `finally` 块会根据需要执行。

2. **`except` 块**：
   - 用于捕获并处理特定类型的异常。
   - 支持多个 `except` 块，针对不同异常类型分别处理：
     ```python
     try:
         # 可能引发多种异常的代码
     except ValueError as e:
         print(f"处理 ValueError 异常: {e}")
     except TypeError as e:
         print(f"处理 TypeError 异常: {e}")
     ```
   - 如果未指定异常类型，会捕获所有异常，但建议仅在调试时使用：
     ```python
     except Exception as e:
         print(f"捕获到异常: {e}")
     ```

3. **`finally` 块**：
   - 通常用于释放资源或清理操作。
   - 无论是否发生异常，`finally` 块中的代码都会被执行。

---

### 用法示例

#### 1. 捕获特定异常
```python
try:
    result = 10 / 0
except ZeroDivisionError as e:
    print(f"捕获到除以零的异常: {e}")
```

#### 2. 捕获多个异常
```python
try:
    data = int("hello")  # 可能引发 ValueError
    result = 10 / 0      # 可能引发 ZeroDivisionError
except ValueError as e:
    print(f"值错误: {e}")
except ZeroDivisionError as e:
    print(f"零除错误: {e}")
```

#### 3. 使用 `finally`
```python
try:
    f = open("data.txt", "r")
    data = f.read()
except FileNotFoundError as e:
    print(f"文件未找到: {e}")
finally:
    print("无论是否出错，这里都会执行")
    if 'f' in locals() and not f.closed:
        f.close()
```

---

### 扩展：`else` 块
- `try` 块中代码无异常时会执行 `else`。
- 常用于将核心逻辑与异常处理分开：
```python
try:
    num = int("123")
except ValueError as e:
    print(f"转换失败: {e}")
else:
    print(f"转换成功: {num}")
```

---

### 异常处理的注意事项
1. 捕获范围从具体到泛化：
   - 优先捕获具体的异常类型，最后再捕获通用的 `Exception`。
2. 避免滥用 `try`，确保代码的关键部分放入 `try` 块中。
3. 不要忽略异常，应至少记录日志或输出错误信息。

## 传播机制和With

异常传播机制和 `with` 语句中的异常捕获与传播机制是异常处理中的两个重要方面。它们在程序的执行流程中有着不同的角色，尤其是在异常发生时如何传播或捕获异常。我们来详细讲解这些机制。

### 1. 异常传播机制

异常传播（Exception Propagation）是指，当一个函数或代码块中发生异常时，Python 会沿着调用栈向上传播，直到异常被捕获并处理，或者最终没有被捕获，导致程序崩溃。

传播过程：

- 当异常在某个函数内部发生时，Python 会停止当前函数的执行，查找是否有相应的 `except` 块来捕获该异常。
- 如果该函数没有捕获异常，它会把异常抛给调用它的函数，直到栈顶（即 `main` 函数或脚本的执行部分）。
- 如果最终没有找到对应的 `except` 块来处理该异常，程序将中止执行并输出异常信息。

示例：

```python
def func1():
    raise ValueError("发生了错误!")

def func2():
    func1()  # 捕获不到异常，异常会传到上一级

def main():
    try:
        func2()  # 最终捕获异常
    except ValueError as e:
        print(f"捕获到异常: {e}")

main()
```

在这个示例中，`ValueError` 异常发生在 `func1` 中，并通过 `func2` 传递到 `main` 函数中的 `except` 块。

### 2. `with` 语句中的异常捕获与传播机制

`with` 语句是用于简化资源管理（如文件、数据库连接等）的结构，它会自动管理资源的获取和释放。`with` 语句背后通过上下文管理器（Context Manager）实现对资源的管理。在 `with` 语句中，如果发生异常，Python 会根据上下文管理器的实现来决定如何处理异常。

工作原理：

- `with` 会自动调用上下文管理器的 `__enter__` 方法来初始化资源。
- 执行完 `with` 块内的代码后，Python 会自动调用上下文管理器的 `__exit__` 方法，无论 `with` 块内的代码是否成功执行。
- 如果 `with` 块内发生异常，异常会传递到 `__exit__` 方法，`__exit__` 方法可以选择是否处理这个异常。如果选择处理，异常就不会传播出去；如果不处理，异常会继续传播。

**`__exit__` 方法中的异常处理：**

`__exit__` 方法有三个参数：

- `exc_type`: 异常的类型
- `exc_value`: 异常的值
- `traceback`: 异常的 traceback 对象

如果 `__exit__` 返回 `True`，那么异常将被认为已被处理，Python 不会继续传播它。否则，异常会向外传播。

**示例：**

```python
class MyContextManager:
    def __enter__(self):
        print("资源被获取")
        return self
    
    def __exit__(self, exc_type, exc_value, traceback):
        if exc_type is None:
            print("正常退出，不发生异常")
        else:
            print(f"发生了异常: {exc_type} - {exc_value}")
        return True  # 如果返回 True，异常不会继续传播

with MyContextManager() as cm:
    print("执行代码块")
    raise ValueError("模拟异常")  # 异常将在 __exit__ 中捕获并处理
```

**输出：**

```
资源被获取
执行代码块
发生了异常: <class 'ValueError'> - 模拟异常
```

由于 `__exit__` 返回了 `True`，异常不会向外传播。

---

### 3. 为什么 `return True` 可以正常运行

在异常处理机制中，`return True` 的作用是告诉 Python 忽略当前异常并认为它已经被处理了。特别是在 `with` 语句中，`__exit__` 方法返回 `True` 会阻止异常继续传播。

- **`__exit__` 返回 `True`**：Python 认为异常已经被捕获并处理，因此不会继续传播该异常，程序会继续执行。
- **`__exit__` 返回 `False` 或不返回**：异常将继续传播到外部，直到被捕获或程序崩溃。

**例子：**

```python
class MyContextManager:
    def __enter__(self):
        print("进入上下文管理器")
        return self
    
    def __exit__(self, exc_type, exc_value, traceback):
        if exc_type is not None:
            print(f"发生了异常: {exc_type} - {exc_value}")
        return True  # 处理异常，不让它继续传播

with MyContextManager() as cm:
    raise ValueError("发生了错误")
```

输出：
```
进入上下文管理器
发生了异常: <class 'ValueError'> - 发生了错误
```

因为 `return True`，异常被认为已经处理，不会向外传播。

**总结**

- **异常传播机制**：当函数内部出现异常时，异常会向上传播，直到被捕获或程序终止。
- **`with` 中的异常捕获机制**：`with` 语句中的上下文管理器通过 `__enter__` 和 `__exit__` 方法管理资源，`__exit__` 可以选择是否处理异常。如果 `__exit__` 返回 `True`，异常不会继续传播，否则会继续传播。

`return True` 在异常处理中用于阻止异常的传播，通常用于 `with` 语句中的上下文管理器，表示异常已经被处理。

## 如果是enter函数发生异常，结果会怎么样

如果在 `__enter__` 方法中发生异常，`with` 语句将无法成功进入上下文块。具体来说，`with` 语句会捕获 `__enter__` 方法抛出的异常，并直接跳到 `__exit__` 方法来处理这个异常。这意味着在 `with` 块中的代码不会执行，因为 `__enter__` 未能成功完成其任务。

**发生异常时的处理流程：**

1. 当进入 `with` 块时，Python 会调用上下文管理器的 `__enter__` 方法。
2. **`__enter__` 方法抛出异常**：
   - 如果在调用 `__enter__` 方法时抛出异常，Python 会跳过 `with` 块的执行，因为上下文未成功建立。
   - 即使 `__enter__` 方法抛出异常，Python **不会调用 `__exit__` 方法**，因为上下文管理器未完全进入工作状态。
   - **为什么不会调用 `__exit__`**：`__exit__` 方法是设计用来在退出上下文时执行清理工作的，但如果 `__enter__` 方法抛出异常，就表示上下文管理器根本没有成功建立，此时没有资源需要清理，因此不会调用 `__exit__`。
4. 由于异常发生在 `__enter__` 阶段，`with` 块的代码部分不会被执行。

**示例：`__enter__` 方法中发生异常**

```python
class MyContextManager:
    def __enter__(self):
        print("进入上下文管理器")
        raise ValueError("在 __enter__ 中发生异常")  # 模拟异常

    def __exit__(self, exc_type, exc_value, traceback):
        print(f"异常类型: {exc_type}")
        print(f"异常值: {exc_value}")
        return False  # 允许异常传播

# 使用 with 语句
try:
    with MyContextManager() as cm:
        print("这是上下文管理器中的代码")
except ValueError as e:
    print(f"捕获到异常: {e}")
```

**输出：**

```
进入上下文管理器
异常类型: <class 'ValueError'>
异常值: 在 __enter__ 中发生异常
捕获到异常: 在 __enter__ 中发生异常
```

**解释：**

1. 在 `__enter__` 中抛出了一个 `ValueError` 异常。
2. 异常被捕获并传递到 `__exit__` 方法，`__exit__` 打印了异常的类型和值。
3. `with` 语句的主体部分没有被执行，因为 `__enter__` 失败了。

**处理 `__enter__` 中异常的方式**

你可以在 `__exit__` 方法中处理这个异常，或者选择让它传播出去。`__exit__` 方法的返回值决定了是否阻止异常传播：
- 如果 `__exit__` 返回 `True`，则表示异常已被处理，异常不会继续传播。
- 如果 `__exit__` 返回 `False` 或不返回值，异常会继续传播到外部（如 `try-except` 块中）。

在 `__enter__` 中发生异常时，`with` 语句的行为本质上会根据 `__exit__` 的处理方式来决定是继续执行后续代码还是终止执行。

**总结：**

当 `__enter__` 方法发生异常时，`with` 语句会跳过 `with` 块中的代码，异常会传递到 `__exit__` 方法，允许你在 `__exit__` 中处理该异常。如果不处理，异常会继续传播。

## with中遇到异常就会直接执行exit方法，并且with代码块之后的语句就不执行

是的，**当 `with` 块中发生异常时，Python 会立即执行 `__exit__` 方法**，并且 `with` 块后面的代码不会执行，除非异常被 `__exit__` 处理并且阻止了异常传播。

**详细解释：**

- **进入 `with` 块时**：Python 会调用上下文管理器的 `__enter__` 方法，获取资源并进入 `with` 块。
- **在 `with` 块内发生异常时**：如果 `with` 块中的代码抛出异常，Python 会立刻跳到上下文管理器的 `__exit__` 方法，传递异常的类型、值和 traceback 供你处理。
- **退出 `with` 块时**：无论 `with` 块内的代码是否发生异常，`__exit__` 方法都会被调用。如果 `__exit__` 返回 `True`，则表示异常已经被处理，异常不会传播出去，`with` 语句后面的代码会继续执行。如果返回 `False` 或不返回，则异常会继续传播，导致 `with` 语句后面的代码不会执行，除非有外部的 `try-except` 块来捕获异常。

**例子：`with` 块中的异常和 `__exit__` 处理**

```python
class MyContextManager:
    def __enter__(self):
        print("进入上下文管理器")
        return self
    
    def __exit__(self, exc_type, exc_value, traceback):
        print(f"异常类型: {exc_type}")
        print(f"异常值: {exc_value}")
        return False  # 不处理异常，让它传播

# 使用 with 语句
try:
    with MyContextManager() as cm:
        print("这是上下文管理器中的代码")
        raise ValueError("模拟异常")  # 在 with 块内抛出异常
        print("这个代码不会被执行")  # 这行代码不会执行
except ValueError as e:
    print(f"捕获到异常: {e}")

print("after with")  # 在异常处理后，这行代码会执行
```

**输出：**

```lua
进入上下文管理器
这是上下文管理器中的代码
异常类型: <class 'ValueError'>
异常值: 模拟异常
捕获到异常: 模拟异常
after with
```

**解释：**

1. `with` 块内的代码 `print("这是上下文管理器中的代码")` 执行成功。
2. 然后抛出 `ValueError("模拟异常")` 异常，Python 立即跳转到 `__exit__` 方法。
3. `__exit__` 方法打印异常信息，并且返回 `False`（表示不处理异常，让它继续传播）。
4. 异常被 `try-except` 块捕获，并打印出异常信息。
5. `print("after with")` 仍然执行，因为异常已经被 `try-except` 块处理。

**关键点：**

- **`__exit__`** 在 `with` 块内发生异常时会被调用。
- **`__exit__` 返回 `True`** 表示异常已经被处理，不会继续传播，`with` 语句后面的代码会继续执行。
- **`__exit__` 返回 `False`** 或不返回任何值时，异常会继续传播，导致 `with` 语句后面的代码不会执行，除非在外部有适当的 `try-except` 块来捕获异常。

**总结：**

- 如果 `with` 块内发生异常，`__exit__` 方法会被调用。
- `with` 代码块之后的语句**不会执行**，除非异常被 `__exit__` 处理并阻止传播，或者外部有 `try-except` 处理异常。

## return True 还会执行

如果在 `__exit__` 方法中返回 `True`，这表示**异常已经被处理**，并且**异常不会继续传播**。因此，`with` 块后面的代码会继续执行。

**关键点：**

- `__exit__` 返回 `True` 时，异常不会被抛出，`with` 块后面的代码会继续执行。
- `__exit__` 返回 `False` 或不返回任何值时，异常会传播，`with` 块后面的代码将不会执行，除非外部有适当的 `try-except` 块来捕获异常。

示例：`__exit__` 返回 `True`

```python
class MyContextManager:
    def __enter__(self):
        print("进入上下文管理器")
        return self
    
    def __exit__(self, exc_type, exc_value, traceback):
        print(f"异常类型: {exc_type}")
        print(f"异常值: {exc_value}")
        # 返回 True，表示异常已处理，不继续传播
        return True  

# 使用 with 语句
try:
    with MyContextManager() as cm:
        print("这是上下文管理器中的代码")
        raise ValueError("模拟异常")  # 在 with 块内抛出异常
        print("这行代码不会被执行")  # 这行代码也不会执行，因为异常发生后进入了 __exit__ 方法
except ValueError as e:
    print(f"捕获到异常: {e}")  # 这行代码不会执行，因为异常已被处理

print("after with")  # 这行代码会执行，因为异常已被处理
```

**输出：**

```
进入上下文管理器
这是上下文管理器中的代码
异常类型: <class 'ValueError'>
异常值: 模拟异常
after with
```

**解释：**

1. `with` 块中的代码 `print("这是上下文管理器中的代码")` 执行。
2. 然后抛出 `ValueError("模拟异常")` 异常，进入 `__exit__` 方法。
3. 在 `__exit__` 中，返回 `True`，表示异常已经被处理，异常不会继续传播。
4. `try-except` 块外的代码 `print("after with")` 继续执行，因为异常被 `__exit__` 方法处理了。

**总结：**

- **返回 `True`**：表示异常已被处理，异常不会传播，`with` 语句后面的代码会继续执行。
- **返回 `False` 或不返回**：异常会继续传播，`with` 语句后面的代码不会执行，除非外部有 `try-except` 处理。

## With和迭代器

`with` 语句和迭代器之间的关系主要体现在上下文管理器的实现上。`with` 语句本质上是用于管理资源，它通过上下文管理器（context manager）来控制资源的获取和释放。而迭代器也是一种对象，可以通过 `__iter__()` 和 `__next__()` 方法来实现可迭代行为，但它们可以与 `with` 语句结合起来，实现更加简洁的资源管理。

### 1. **`with` 语句的工作原理**
`with` 语句背后依赖于上下文管理器（Context Manager），上下文管理器需要实现两个方法：
- `__enter__(self)`：进入 `with` 块时调用，负责资源的获取。
- `__exit__(self, exc_type, exc_value, traceback)`：退出 `with` 块时调用，负责资源的清理，且可以捕获和处理异常。

### 2. **迭代器与上下文管理器**
一个迭代器是一个实现了 `__iter__()` 和 `__next__()` 方法的对象，它允许你逐个访问集合中的元素。`with` 语句通常与上下文管理器结合，但它也可以与迭代器结合，通过创建支持迭代的上下文管理器来管理资源，尤其是在处理需要资源清理的迭代任务时。

#### 迭代器与上下文管理器结合的场景：
- 当你需要在迭代过程中对资源进行处理和清理（例如：文件流、数据库连接、网络请求等），可以用 `with` 来管理这些资源，并在迭代过程中自动执行清理操作。
- 迭代器本身不一定是上下文管理器，但我们可以实现一个将迭代器与上下文管理器结合的类，使得它能在 `with` 语句中使用。

### 3. **结合示例：`with` 语句与迭代器**
假设我们有一个迭代器，它需要在完成后进行清理工作（如关闭文件或释放网络连接），这时可以让迭代器实现上下文管理器接口（`__enter__` 和 `__exit__`）。

#### 示例：一个迭代器作为上下文管理器

```python
class MyIterator:
    def __init__(self, start, end):
        self.start = start
        self.end = end
        self.current = start
    
    def __iter__(self):
        return self

    def __next__(self):
        if self.current >= self.end:
            raise StopIteration
        self.current += 1
        return self.current - 1
    
    # 上下文管理器方法
    def __enter__(self):
        print("进入上下文管理器：初始化迭代器")
        return self
    
    def __exit__(self, exc_type, exc_value, traceback):
        print("退出上下文管理器：清理资源")
        # 可以处理异常
        if exc_type is not None:
            print(f"异常类型: {exc_type}, 异常值: {exc_value}")
        return False  # 返回 False，异常继续传播

# 使用迭代器作为上下文管理器
with MyIterator(0, 5) as it:
    for num in it:
        if num == 2:
            raise ValueError("模拟异常")
        print(num)
```

输出：
```
进入上下文管理器：初始化迭代器
0
1
发生异常: <class 'ValueError'>, 异常值: 模拟异常
退出上下文管理器：清理资源
```

#### 解释：
1. **`__enter__`**：在进入 `with` 块时调用，初始化了迭代器。
2. **`__exit__`**：在退出 `with` 块时调用，负责清理资源。如果发生了异常，它会被捕获并处理。注意，返回 `False` 表示异常会继续传播。如果返回 `True`，异常会被抑制。

### 4. **迭代器的自动清理**
当 `with` 语句与迭代器结合时，可以确保迭代结束或异常发生时，自动清理资源。例如，处理文件流时，文件读取结束后自动关闭文件，而不需要显式调用 `close()`。

#### 示例：文件迭代器作为上下文管理器

```python
class FileIterator:
    def __init__(self, filename):
        self.filename = filename
        self.file = None

    def __enter__(self):
        print(f"打开文件: {self.filename}")
        self.file = open(self.filename, 'r')
        return self

    def __iter__(self):
        return self

    def __next__(self):
        line = self.file.readline()
        if not line:
            raise StopIteration
        return line.strip()

    def __exit__(self, exc_type, exc_value, traceback):
        if self.file:
            print("关闭文件")
            self.file.close()
        if exc_type is not None:
            print(f"异常类型: {exc_type}, 异常值: {exc_value}")
        return False

# 假设文件内容是：
# line 1
# line 2
# line 3
with FileIterator("test.txt") as file_iter:
    for line in file_iter:
        print(line)
```

输出：
```
打开文件: test.txt
line 1
line 2
line 3
关闭文件
```

---

### 总结
- **`with` 语句**：用于简化资源管理，自动执行资源的获取和释放。
- **迭代器**：是可迭代对象，可以逐步返回集合中的元素。迭代器实现了 `__iter__()` 和 `__next__()` 方法。
- **结合**：通过实现上下文管理器协议（`__enter__` 和 `__exit__`），迭代器可以与 `with` 语句结合，使得迭代过程中的资源管理更加高效、简洁，且能够自动进行清理。

这种结合的方式特别适用于需要清理资源的场景，例如处理文件、网络连接、数据库操作等。

>###  生成器与 with 的关系：通过 contextlib 实现上下文管理
>
>`contextlib.contextmanager` **装饰器**
>
>生成器可以通过 `contextlib.contextmanager` **转换为上下文管理器**。生成器中的 `yield` 语句将上下文分为 **进入（前半段）** 和 **退出（后半段）** 两部分。
>
>**示例：用生成器模拟上下文管理**
>
>```python
>from contextlib import contextmanager
>
>@contextmanager
>def custom_context():
>    print("Entering the context")
>    yield 42  # 暂停，并将控制权交给 `with` 语句中的代码块
>    print("Exiting the context")
>
># 使用生成器的上下文管理
>with custom_context() as value:
>    print(f"Inside the context, got value: {value}")
>```
>
>**输出：**
>
>```
>Entering the context
>Inside the context,got value: 42
>Exiting the context
>```
>
>**过程解析**
>
>1. **`Entering the context`**：执行 `yield` 之前的代码，表示进入上下文。
>2. **`Inside the context`**：代码块运行时，`yield` 返回的值赋给 `value`。
>3. **`Exiting the context`**：`with` 代码块结束后，恢复执行 `yield` 之后的代码。
